Traceback (most recent call last):
  File "C:\Users\ppzmis\AppData\Local\miniconda3\envs\instructor\lib\site-packages\jupyter_cache\executors\utils.py", line 58, in single_nb_execution
    executenb(
  File "C:\Users\ppzmis\AppData\Local\miniconda3\envs\instructor\lib\site-packages\nbclient\client.py", line 1314, in execute
    return NotebookClient(nb=nb, resources=resources, km=km, **kwargs).execute()
  File "C:\Users\ppzmis\AppData\Local\miniconda3\envs\instructor\lib\site-packages\jupyter_core\utils\__init__.py", line 165, in wrapped
    return loop.run_until_complete(inner)
  File "C:\Users\ppzmis\AppData\Local\miniconda3\envs\instructor\lib\asyncio\base_events.py", line 649, in run_until_complete
    return future.result()
  File "C:\Users\ppzmis\AppData\Local\miniconda3\envs\instructor\lib\site-packages\nbclient\client.py", line 709, in async_execute
    await self.async_execute_cell(
  File "C:\Users\ppzmis\AppData\Local\miniconda3\envs\instructor\lib\site-packages\nbclient\client.py", line 1062, in async_execute_cell
    await self._check_raise_for_error(cell, cell_index, exec_reply)
  File "C:\Users\ppzmis\AppData\Local\miniconda3\envs\instructor\lib\site-packages\nbclient\client.py", line 918, in _check_raise_for_error
    raise CellExecutionError.from_cell_and_msg(cell, exec_reply_content)
nbclient.exceptions.CellExecutionError: An error occurred while executing the following cell:
------------------
import sys
print(sys.path)     # This is the list of places python searches
import example_import   # Note it doesn't find this because it is inside the resources folder and so errors
------------------

----- stdout -----
['C:\\Users\\ppzmis\\AppData\\Local\\miniconda3\\envs\\instructor\\python310.zip', 'C:\\Users\\ppzmis\\AppData\\Local\\miniconda3\\envs\\instructor\\DLLs', 'C:\\Users\\ppzmis\\AppData\\Local\\miniconda3\\envs\\instructor\\lib', 'C:\\Users\\ppzmis\\AppData\\Local\\miniconda3\\envs\\instructor', '', 'C:\\Users\\ppzmis\\AppData\\Local\\miniconda3\\envs\\instructor\\lib\\site-packages', 'C:\\Users\\ppzmis\\AppData\\Local\\miniconda3\\envs\\instructor\\lib\\site-packages\\win32', 'C:\\Users\\ppzmis\\AppData\\Local\\miniconda3\\envs\\instructor\\lib\\site-packages\\win32\\lib', 'C:\\Users\\ppzmis\\AppData\\Local\\miniconda3\\envs\\instructor\\lib\\site-packages\\Pythonwin']
------------------

[1;31m---------------------------------------------------------------------------[0m
[1;31mModuleNotFoundError[0m                       Traceback (most recent call last)
Cell [1;32mIn[4], line 3[0m
[0;32m      1[0m [38;5;28;01mimport[39;00m [38;5;21;01msys[39;00m
[0;32m      2[0m [38;5;28mprint[39m(sys[38;5;241m.[39mpath)     [38;5;66;03m# This is the list of places python searches[39;00m
[1;32m----> 3[0m [38;5;28;01mimport[39;00m [38;5;21;01mexample_import[39;00m   [38;5;66;03m# Note it doesn't find this because it is inside the resources folder and so errors[39;00m

[1;31mModuleNotFoundError[0m: No module named 'example_import'

