Traceback (most recent call last):
  File "C:\Users\ppzmis\AppData\Local\miniconda3\envs\instructor\lib\site-packages\jupyter_cache\executors\utils.py", line 58, in single_nb_execution
    executenb(
  File "C:\Users\ppzmis\AppData\Local\miniconda3\envs\instructor\lib\site-packages\nbclient\client.py", line 1314, in execute
    return NotebookClient(nb=nb, resources=resources, km=km, **kwargs).execute()
  File "C:\Users\ppzmis\AppData\Local\miniconda3\envs\instructor\lib\site-packages\jupyter_core\utils\__init__.py", line 165, in wrapped
    return loop.run_until_complete(inner)
  File "C:\Users\ppzmis\AppData\Local\miniconda3\envs\instructor\lib\asyncio\base_events.py", line 649, in run_until_complete
    return future.result()
  File "C:\Users\ppzmis\AppData\Local\miniconda3\envs\instructor\lib\site-packages\nbclient\client.py", line 709, in async_execute
    await self.async_execute_cell(
  File "C:\Users\ppzmis\AppData\Local\miniconda3\envs\instructor\lib\site-packages\nbclient\client.py", line 1062, in async_execute_cell
    await self._check_raise_for_error(cell, cell_index, exec_reply)
  File "C:\Users\ppzmis\AppData\Local\miniconda3\envs\instructor\lib\site-packages\nbclient\client.py", line 918, in _check_raise_for_error
    raise CellExecutionError.from_cell_and_msg(cell, exec_reply_content)
nbclient.exceptions.CellExecutionError: An error occurred while executing the following cell:
------------------
import openmeteo_requests

import requests_cache
import pandas as pd
from retry_requests import retry
import matplotlib.pyplot as plt

# Setup the Open-Meteo API client with cache and retry on error
cache_session = requests_cache.CachedSession('.cache', expire_after = -1)
retry_session = retry(cache_session, retries = 5, backoff_factor = 0.2)
openmeteo = openmeteo_requests.Client(session = retry_session)
------------------


[1;31m---------------------------------------------------------------------------[0m
[1;31mModuleNotFoundError[0m                       Traceback (most recent call last)
Cell [1;32mIn[1], line 1[0m
[1;32m----> 1[0m [38;5;28;01mimport[39;00m [38;5;21;01mopenmeteo_requests[39;00m
[0;32m      3[0m [38;5;28;01mimport[39;00m [38;5;21;01mrequests_cache[39;00m
[0;32m      4[0m [38;5;28;01mimport[39;00m [38;5;21;01mpandas[39;00m [38;5;28;01mas[39;00m [38;5;21;01mpd[39;00m

[1;31mModuleNotFoundError[0m: No module named 'openmeteo_requests'

