Traceback (most recent call last):
  File "C:\Users\ppzmis\AppData\Local\miniconda3\envs\instructor\lib\site-packages\jupyter_cache\executors\utils.py", line 58, in single_nb_execution
    executenb(
  File "C:\Users\ppzmis\AppData\Local\miniconda3\envs\instructor\lib\site-packages\nbclient\client.py", line 1314, in execute
    return NotebookClient(nb=nb, resources=resources, km=km, **kwargs).execute()
  File "C:\Users\ppzmis\AppData\Local\miniconda3\envs\instructor\lib\site-packages\jupyter_core\utils\__init__.py", line 165, in wrapped
    return loop.run_until_complete(inner)
  File "C:\Users\ppzmis\AppData\Local\miniconda3\envs\instructor\lib\asyncio\base_events.py", line 649, in run_until_complete
    return future.result()
  File "C:\Users\ppzmis\AppData\Local\miniconda3\envs\instructor\lib\site-packages\nbclient\client.py", line 709, in async_execute
    await self.async_execute_cell(
  File "C:\Users\ppzmis\AppData\Local\miniconda3\envs\instructor\lib\site-packages\nbclient\client.py", line 1062, in async_execute_cell
    await self._check_raise_for_error(cell, cell_index, exec_reply)
  File "C:\Users\ppzmis\AppData\Local\miniconda3\envs\instructor\lib\site-packages\nbclient\client.py", line 918, in _check_raise_for_error
    raise CellExecutionError.from_cell_and_msg(cell, exec_reply_content)
nbclient.exceptions.CellExecutionError: An error occurred while executing the following cell:
------------------
time = np.linspace(0,4*np.pi,100)
df_example = pd.DataFrame({'time':time,'amplitude':np.sin(0.3*time)})
df_example.to_csv('resources/textfiles/write_example.csv', index=False)
------------------


[1;31m---------------------------------------------------------------------------[0m
[1;31mNameError[0m                                 Traceback (most recent call last)
Cell [1;32mIn[9], line 1[0m
[1;32m----> 1[0m time [38;5;241m=[39m [43mnp[49m[38;5;241m.[39mlinspace([38;5;241m0[39m,[38;5;241m4[39m[38;5;241m*[39mnp[38;5;241m.[39mpi,[38;5;241m100[39m)
[0;32m      2[0m df_example [38;5;241m=[39m pd[38;5;241m.[39mDataFrame({[38;5;124m'[39m[38;5;124mtime[39m[38;5;124m'[39m:time,[38;5;124m'[39m[38;5;124mamplitude[39m[38;5;124m'[39m:np[38;5;241m.[39msin([38;5;241m0.3[39m[38;5;241m*[39mtime)})
[0;32m      3[0m df_example[38;5;241m.[39mto_csv([38;5;124m'[39m[38;5;124mresources/textfiles/write_example.csv[39m[38;5;124m'[39m, index[38;5;241m=[39m[38;5;28;01mFalse[39;00m)

[1;31mNameError[0m: name 'np' is not defined

